Workbook

Sheet Bitácora
A1: BITACORA VENTA LOCAL
A2: VIVERO SONSONATE | D2: ENCARGADO: Erick Cerrato-Douglas López | G2: SUPERVISA: Douglas López | N2: Mes: Diciembre | Q2: AÑO:2025
A3: Datos | F3: Producción | K3: Siembra a Campo | M3: Cambio de Presentación | P3: Descargo de plantas | Q3: Datos
A4: Fecha | B4: Trabajador | C4: Cantidad | D4: Cortar Follaje | E4: Cortar y sembrar Enraizador | F4: Producción: Nombre de la planta (Cantidad y tamaño) | G4: Presentación (Maceta, bolsa, etc) | H4: Origen de las plantas | I4: Material utilizado | J4: Siembra: Tiempo en horas | K4: Sembrar a campo/Sacar de campo | L4: A campo: Lugar de siembra | M4: Código antiguo | N4: Cambio de presentación: Antigua presentación | O4: Cambio de presentación: Nueva Presentación | P4: Descargo de plantas | Q4: Código | R4: Requisición | S4: Otras actividades
A5: 45992 | B5: liliam-Lidia | C5: 10 | F5: Ficus Lyriata 1 plantas de 50 cm | G5: MP#3 dec | H5: Vivero 60% | I5: 11300 | J5: 4 horas | M5: PFMP03200 | Q5: =M5 -> PFMP03200
A6: 45992 | B6: Liliam-Lidia | C6: 15 | F6: Aralia fabia 7 plantas de 70 cm | G6: Mp#4 dec | H6: Vivero 60% | I6: 15600 | J6: 4 horas | M6: PAMP40017 | Q6: =M6 -> PAMP40017
A7: 45992 | B7: Julio-Alberto | C7: 500 | F7: Gardenias 1 plantas de 10 pulgadas | G7: bolsa 9*12 | H7: Vivero 60% | I7: 6246 | J7: 16 horas | M7: PGBP04001 | Q7: =M7 -> PGBP04001
A8: 45994 | B8: Liliam-Lidia-Alberto | C8: 20 | F8: Queso suizo 5 plantas de 6 pulgadas | G8: PC#1 | H8: Vivero 60% | I8: 6000 | J8: 4 horas | M8: PQCA01001 | Q8: =M8 -> PQCA01001
A9: 45994 | B9: Liliam-Lidia-Alberto | C9: 15 | F9: Aralia fabia 5 plantas de 70 cm | G9: MP#3 dec | H9: Vivero 60% | I9: 11300 | J9: 8 horas | M9: PAMP03017 | Q9: =M9 -> PAMP03017
A10: 45994 | B10: Liliam-Lidia-Alberto | C10: 30 | F10: Aralia fabia 7 plantas de 70 cm | G10: MP#4 dec | H10: Vivero 60% | I10: 15600 | J10: 8 horas | M10: PAMP40017 | Q10: =M10 -> PAMP40017
A11: 45995 | B11: Liliam-Lidia | C11: 31 | M11: PPBP07006 | N11: 31 Palmera pheonix bolsa 14*16 | O11: 31 Palmera pheonix bolsa 14*16 | Q11: =M11 -> PPBP07006
A12: 45995 | B12: Liliam-Lidia | C12: 1 | M12: PAMP04128 | N12: 1 Aralia feliscifolia MP#4 dec | O12: 1 Aralia feliscifolia MP#4 dec | Q12: =M12 -> PAMP04128
A13: 45995 | B13: Fermin-Julio | C13: 1 | M13: PCMP06040 | P13: 1 Croto punctatum malla circ MP#6 | Q13: =M13 -> PCMP06040 | R13: 6000274 | S13: venian muertas
A14: 45995 | B14: Fermin-Julio | C14: 7 | M14: PSMP05013 | P14: 7 schefflera mini trenza MP#5 | Q14: =M14 -> PSMP05013 | R14: 6000274 | S14: venian muertas
A15: 45995 | B15: Fermin-Julio | C15: 1 | M15: PFMP03120 | P15: 1 Ficus brasil MP#3 dec | Q15: =M15 -> PFMP03120 | R15: 6000274 | S15: venian muertas
A16: 45995 | B16: Fermin-Julio | C16: 10 | M16: PCBP04038 | P16: 10 Croto petra amarillo bolsa 9*12 | Q16: =M16 -> PCBP04038 | R16: 6000274 | S16: venian muertas
A17: 45995 | B17: Fermin-Julio | C17: 1 | M17: PPMP04017 | P17: 1 Peperomia MP#4 | Q17: =M17 -> PPMP04017 | R17: 6000274 | S17: venian muertas
A18: 45995 | B18: Fermin-Julio | C18: 1 | M18: PPCA01037 | P18: 1 potho joy variegado PC#1 | Q18: =M18 -> PPCA01037 | R18: 6000274 | S18: venian muertas
A19: 45995 | B19: Fermin-Julio | C19: 10 | M19: PCMP05035 | P19: 10 Croto batick trenza MP#5 | Q19: =M19 -> PCMP05035 | R19: 6000274 | S19: venian muertas
A20: 45995 | B20: Fermin-Julio | C20: 13 | M20: PCBP04035 | P20: 13 Croto batick bolsa 9*12 | Q20: =M20 -> PCBP04035 | R20: 6000274 | S20: venian muertas
A21: 45995 | B21: Fermin-Julio | C21: 3 | M21: PDMP04103 | P21: 3 Diaffembaqui MP#4 | Q21: =M21 -> PDMP04103 | R21: 6000274 | S21: venian muertas
A22: 45995 | B22: Fermin-Julio | C22: 1 | M22: PDMP04002 | P22: 1 Palmera areca MP#4 dec | Q22: =M22 -> PDMP04002 | R22: 6000274 | S22: venian muertas
A23: 45995 | B23: Fermin-Julio | C23: 1 | M23: PPCA01039 | P23: 1 Potho limon PC#1 | Q23: =M23 -> PPCA01039 | R23: 6000274 | S23: venian muertas
A24: 45995 | B24: Fermin-Julio | C24: 1 | M24: PAMP06017 | P24: 1 Aralia penockii malla circ MP#6 | Q24: =M24 -> PAMP06017 | R24: 6000274 | S24: venian muertas
A25: 45995 | B25: Fermin-Julio | C25: 18 | M25: PAMP04021 | P25: 18 Arreglos combinados MP34 | Q25: =M25 -> PAMP04021 | R25: 6000274 | S25: venian muertas
A26: 45995 | B26: liliam-Lidia | C26: 9 | M26: PDMP04103 | P26: 9 Diaffembaquias MP#4 | Q26: =M26 -> PDMP04103 | S26: En adaptación se mruieron
A27: 45995 | B27: liliam-Lidia | C27: =31+26 -> 57 | M27: PPMP04017 | P27: 57 Peperomia MP#4 | Q27: =M27 -> PPMP04017 | S27: En adaptación se mruieron
A28: 45995 | B28: liliam-Lidia | C28: 13 | M28: PJMP04006 | P28: 13 Junipero MP#4 | Q28: =M28 -> PJMP04006 | S28: En adaptación se mruieron
A29: 45995 | B29: liliam-Lidia | C29: 9 | M29: PCMP05035 | P29: 9 Croto batick trenza MP#5 | Q29: =M29 -> PCMP05035 | S29: En adaptación se mruieron
A30: 45995 | B30: liliam-Lidia | C30: 15 | M30: PCMP05036 | P30: 15 Croto gold dust trenza MP#5 | Q30: =M30 -> PCMP05036 | S30: En adaptación se mruieron
A31: 45995 | B31: liliam-Lidia | C31: 38 | M31: PCMP05039 | P31: 38 Croto petra 3 puntas MP#5 | Q31: =M31 -> PCMP05039 | S31: En adaptación se mruieron
A32: 45995 | B32: liliam-Lidia | C32: 18 | M32: PCMP05040 | P32: 18 Croto punctatum trenza MP#5 | Q32: =M32 -> PCMP05040 | S32: En adaptación se mruieron
A33: 45995 | B33: liliam-Lidia | C33: 10 | M33: PDMP04103 | P33: 10 Diaffembaquias MP#4 | Q33: =M33 -> PDMP04103 | S33: En adaptación se mruieron
A34: 45995 | B34: liliam-Lidia | C34: 11 | M34: PAMP11038 | P34: 11 Alamanda enana MP#11 | Q34: =M34 -> PAMP11038 | S34: Por viejas
A35: 45995 | B35: liliam-Lidia | C35: 3 | M35: PSBP04003 | P35: 3 Santa marta bolsa 9*12 | Q35: =M35 -> PSBP04003 | S35: Por viejas
A36: 45995 | B36: liliam-Lidia | C36: 30 | M36: PCBP04040 | P36: 40 Croto punctatum bolsa 9*12 | Q36: =M36 -> PCBP04040 | S36: Por viento
A37: 45995 | B37: liliam-Lidia | C37: 40 | M37: PCBP04037 | P37: 50 Croto Iceton bolsa 9*12 | Q37: =M37 -> PCBP04037 | S37: Por viento
A38: 45995 | B38: liliam-Lidia | C38: 114 | M38: PBMP04011 | P38: 114 Suculentas Bryophillum MP#4 | Q38: =M38 -> PBMP04011 | S38: No se vendieron se murieron por falta de mantenimiento
A39: 45995 | B39: liliam-Lidia | C39: 18 | M39: PABP04040 | P39: 18 Acalipha bolsa 9*12 | Q39: =M39 -> PABP04040 | S39: Se las comio el zompopo
... A41: 45995 | B41: liliam-Lidia | C41: 25 | M41: PCBP07100 | P41: 25 Arbol de coral bolsa 14*16 | Q41: =M41 -> PCBP07100 | S41: Nunca se vendieron y se pegaron al suelo no se pudieron cambiar de bolsa
...

Sheet Producción
A1: PRODUCCION DE MERCADO LOCAL
A2: Día | B2: Trabajador | C2: Código | D2: Cantidad | E2: Nombre de la planta- Tamaño y cantidad | F2: Presentación (Maceta, bolsa, etc) | G2: Origen de las plantas | H2: Material utilizado | I2: Siembra: Tiempo en horas | J2: Requisición
A3: =Bitácora!A5 -> 45992 | B3: =Bitácora!B5 -> liliam-Lidia | C3: =Bitácora!Q5 -> PFMP03200 | D3: =Bitácora!C5 -> 10 | E3: =Bitácora!F5 -> Ficus Lyriata 1 plantas de 50 cm | F3: =Bitácora!G5 -> MP#3 dec | G3: =Bitácora!H5 -> Vivero 60% | H3: =Bitácora!I5 -> 11300 | I3: =Bitácora!J5 -> 4 horas | J3: =Bitácora!R5 -> 0
A4: =Bitácora!A6 -> 45992 | B4: =Bitácora!B6 -> Liliam-Lidia | C4: =Bitácora!Q6 -> PAMP40017 | D4: =Bitácora!C6 -> 15 | E4: =Bitácora!F6 -> Aralia fabia 7 plantas de 70 cm | F4: =Bitácora!G6 -> Mp#4 dec | G4: =Bitácora!H6 -> Vivero 60% | H4: =Bitácora!I6 -> 15600 | I4: =Bitácora!J6 -> 4 horas | J4: =Bitácora!R6 -> 0
A5: =Bitácora!A7 -> 45992 | B5: =Bitácora!B7 -> Julio-Alberto | C5: =Bitácora!Q7 -> PGBP04001 | D5: =Bitácora!C7 -> 500 | E5: =Bitácora!F7 -> Gardenias 1 plantas de 10 pulgadas | F5: =Bitácora!G7 -> bolsa 9*12 | G5: =Bitácora!H7 -> Vivero 60% | H5: =Bitácora!I7 -> 6246 | I5: =Bitácora!J7 -> 16 horas | J5: =Bitácora!R7 -> 0
A6: =Bitácora!A8 -> 45994 | B6: =Bitácora!B8 -> Liliam-Lidia-Alberto | C6: =Bitácora!Q8 -> PQCA01001 | D6: =Bitácora!C8 -> 20 | E6: =Bitácora!F8 -> Queso suizo 5 plantas de 6 pulgadas | F6: =Bitácora!G8 -> PC#1 | G6: =Bitácora!H8 -> Vivero 60% | H6: =Bitácora!I8 -> 6000 | I6: =Bitácora!J8 -> 4 horas | J6: =Bitácora!R8 -> 0
A7: =Bitácora!A9 -> 45994 | B7: =Bitácora!B9 -> Liliam-Lidia-Alberto | C7: =Bitácora!Q9 -> PAMP03017 | D7: =Bitácora!C9 -> 15 | E7: =Bitácora!F9 -> Aralia fabia 5 plantas de 70 cm | F7: =Bitácora!G9 -> MP#3 dec | G7: =Bitácora!H9 -> Vivero 60% | H7: =Bitácora!I9 -> 11300 | I7: =Bitácora!J9 -> 8 horas | J7: =Bitácora!R9 -> 0
A8: =Bitácora!A10 -> 45994 | B8: =Bitácora!B10 -> Liliam-Lidia-Alberto | C8: =Bitácora!Q10 -> PAMP40017 | D8: =Bitácora!C10 -> 30 | E8: =Bitácora!F10 -> Aralia fabia 7 plantas de 70 cm | F8: =Bitácora!G10 -> MP#4 dec | G8: =Bitácora!H10 -> Vivero 60% | H8: =Bitácora!I10 -> 15600 | I8: =Bitácora!J10 -> 8 horas | J8: =Bitácora!R10 -> 0
A9: =Bitácora!A11 -> 45995 | B9: =Bitácora!B11 -> Liliam-Lidia | C9: =Bitácora!Q11 -> PPBP07006 | D9: =Bitácora!C11 -> 31 | E9: =Bitácora!F11 -> 0 | F9: =Bitácora!G11 -> 0 | G9: =Bitácora!H11 -> 0 | H9: =Bitácora!I11 -> 0 | I9: =Bitácora!J11 -> 0 | J9: =Bitácora!R11 -> 0
A10: =Bitácora!A12 -> 45995 | B10: =Bitácora!B12 -> Liliam-Lidia | C10: =Bitácora!Q12 -> PAMP04128 | D10: =Bitácora!C12 -> 1 | E10: =Bitácora!F12 -> 0 | F10: =Bitácora!G12 -> 0 | G10: =Bitácora!H12 -> 0 | H10: =Bitácora!I12 -> 0 | I10: =Bitácora!J12 -> 0 | J10: =Bitácora!R12 -> 0
A11: =Bitácora!A13 -> 45995 | B11: =Bitácora!B13 -> Fermin-Julio | C11: =Bitácora!Q13 -> PCMP06040 | D11: =Bitácora!C13 -> 1 | E11: =Bitácora!F13 -> 0 | F11: =Bitácora!G13 -> 0 | G11: =Bitácora!H13 -> 0 | H11: =Bitácora!I13 -> 0 | I11: =Bitácora!J13 -> 0 | J11: =Bitácora!R13 -> 6000274
A12: =Bitácora!A14 -> 45995 | B12: =Bitácora!B14 -> Fermin-Julio | C12: =Bitácora!Q14 -> PSMP05013 | D12: =Bitácora!C14 -> 7 | E12: =Bitácora!F14 -> 0 | F12: =Bitácora!G14 -> 0 | G12: =Bitácora!H14 -> 0 | H12: =Bitácora!I14 -> 0 | I12: =Bitácora!J14 -> 0 | J12: =Bitácora!R14 -> 6000274
A13: =Bitácora!A15 -> 45995 | B13: =Bitácora!B15 -> Fermin-Julio | C13: =Bitácora!Q15 -> PFMP03120 | D13: =Bitácora!C15 -> 1 | E13: =Bitácora!F15 -> 0 | F13: =Bitácora!G15 -> 0 | G13: =Bitácora!H15 -> 0 | H13: =Bitácora!I15 -> 0 | I13: =Bitácora!J15 -> 0 | J13: =Bitácora!R15 -> 6000274
A14: =Bitácora!A16 -> 45995 | B14: =Bitácora!B16 -> Fermin-Julio | C14: =Bitácora!Q16 -> PCBP04038 | D14: =Bitácora!C16 -> 10 | E14: =Bitácora!F16 -> 0 | F14: =Bitácora!G16 -> 0 | G14: =Bitácora!H16 -> 0 | H14: =Bitácora!I16 -> 0 | I14: =Bitácora!J16 -> 0 | J14: =Bitácora!R16 -> 6000274
... A51: =Bitácora!A53 -> 0 | B51: =Bitácora!B53 -> 0 | C51: =Bitácora!Q53 -> 0 | D51: =Bitácora!C53 -> 0 | E51: =Bitácora!F53 -> 0 | F51: =Bitácora!G53 -> 0 | G51: =Bitácora!H53 -> 0 | H51: =Bitácora!I53 -> 0 | I51: =Bitácora!J53 -> 0 | J51: =Bitácora!R53 -> 0

Sheet Descargo
A1: DESCARGO DE MERCADO LOCAL
A2: Fecha | B2: Trabajador | C2: Cantidad | D2: Descargo de plantas | E2: Motivo de descargo | F2: Código
A3: =Bitácora!A5 -> 45992 | B3: =Bitácora!B5 -> liliam-Lidia | C3: =Bitácora!C5 -> 10 | D3: =Bitácora!P5 -> 0 | E3: =Bitácora!S5 -> 0 | F3: =Bitácora!Q5 -> PFMP03200
A4: =Bitácora!A6 -> 45992 | B4: =Bitácora!B6 -> Liliam-Lidia | C4: =Bitácora!C6 -> 15 | D4: =Bitácora!P6 -> 0 | E4: =Bitácora!S6 -> 0 | F4: =Bitácora!Q6 -> PAMP40017
A5: =Bitácora!A7 -> 45992 | B5: =Bitácora!B7 -> Julio-Alberto | C5: =Bitácora!C7 -> 500 | D5: =Bitácora!P7 -> 0 | E5: =Bitácora!S7 -> 0 | F5: =Bitácora!Q7 -> PGBP04001
A6: =Bitácora!A8 -> 45994 | B6: =Bitácora!B8 -> Liliam-Lidia-Alberto | C6: =Bitácora!C8 -> 20 | D6: =Bitácora!P8 -> 0 | E6: =Bitácora!S8 -> 0 | F6: =Bitácora!Q8 -> PQCA01001
A7: =Bitácora!A9 -> 45994 | B7: =Bitácora!B9 -> Liliam-Lidia-Alberto | C7: =Bitácora!C9 -> 15 | D7: =Bitácora!P9 -> 0 | E7: =Bitácora!S9 -> 0 | F7: =Bitácora!Q9 -> PAMP03017
A8: =Bitácora!A10 -> 45994 | B8: =Bitácora!B10 -> Liliam-Lidia-Alberto | C8: =Bitácora!C10 -> 30 | D8: =Bitácora!P10 -> 0 | E8: =Bitácora!S10 -> 0 | F8: =Bitácora!Q10 -> PAMP40017
A9: =Bitácora!A11 -> 45995 | B9: =Bitácora!B11 -> Liliam-Lidia | C9: =Bitácora!C11 -> 31 | D9: =Bitácora!P11 -> 0 | E9: =Bitácora!S11 -> 0 | F9: =Bitácora!Q11 -> PPBP07006
A10: =Bitácora!A12 -> 45995 | B10: =Bitácora!B12 -> Liliam-Lidia | C10: =Bitácora!C12 -> 1 | D10: =Bitácora!P12 -> 0 | E10: =Bitácora!S12 -> 0 | F10: =Bitácora!Q12 -> PAMP04128
A11: =Bitácora!A13 -> 45995 | B11: =Bitácora!B13 -> Fermin-Julio | C11: =Bitácora!C13 -> 1 | D11: =Bitácora!P13 -> 1 Croto punctatum malla circ MP#6 | E11: =Bitácora!S13 -> venian muertas | F11: =Bitácora!Q13 -> PCMP06040
A12: =Bitácora!A14 -> 45995 | B12: =Bitácora!B14 -> Fermin-Julio | C12: =Bitácora!C14 -> 7 | D12: =Bitácora!P14 -> 7 schefflera mini trenza MP#5 | E12: =Bitácora!S14 -> venian muertas | F12: =Bitácora!Q14 -> PSMP05013
A13: =Bitácora!A15 -> 45995 | B13: =Bitácora!B15 -> Fermin-Julio | C13: =Bitácora!C15 -> 1 | D13: =Bitácora!P15 -> 1 Ficus brasil MP#3 dec | E13: =Bitácora!S15 -> venian muertas | F13: =Bitácora!Q15 -> PFMP03120
A14: =Bitácora!A16 -> 45995 | B14: =Bitácora!B16 -> Fermin-Julio | C14: =Bitácora!C16 -> 10 | D14: =Bitácora!P16 -> 10 Croto petra amarillo bolsa 9*12 | E14: =Bitácora!S16 -> venian muertas | F14: =Bitácora!Q16 -> PCBP04038
... A52: =Bitácora!A54 -> 0 | B52: =Bitácora!B54 -> 0 | C52: =Bitácora!C54 -> 0 | D52: =Bitácora!P54 -> 0 | E52: =Bitácora!S54 -> 0 | F52: =Bitácora!Q54 -> 0

Sheet Cambio de presentación
A1: CAMBIO DE PRESENTACION
A2: Fecha | B2: Trabajador | C2: Cantidad | D2: Código antiguo | E2: Cambio de presentación: Antigua presentación | F2: Cambio de presentación: Nueva Presentación | G2: Código | H2: Requisición
A3: =Bitácora!A5 -> 45992 | B3: =Bitácora!B5 -> liliam-Lidia | C3: =Bitácora!C5 -> 10 | D3: =Bitácora!M5 -> PFMP03200 | E3: =Bitácora!N5 -> 0 | F3: =Bitácora!O5 -> 0 | G3: =Bitácora!Q5 -> PFMP03200 | H3: =Bitácora!R5 -> 0
A4: =Bitácora!A6 -> 45992 | B4: =Bitácora!B6 -> Liliam-Lidia | C4: =Bitácora!C6 -> 15 | D4: =Bitácora!M6 -> PAMP40017 | E4: =Bitácora!N6 -> 0 | F4: =Bitácora!O6 -> 0 | G4: =Bitácora!Q6 -> PAMP40017 | H4: =Bitácora!R6 -> 0
A5: =Bitácora!A7 -> 45992 | B5: =Bitácora!B7 -> Julio-Alberto | C5: =Bitácora!C7 -> 500 | D5: =Bitácora!M7 -> PGBP04001 | E5: =Bitácora!N7 -> 0 | F5: =Bitácora!O7 -> 0 | G5: =Bitácora!Q7 -> PGBP04001 | H5: =Bitácora!R7 -> 0
A6: =Bitácora!A8 -> 45994 | B6: =Bitácora!B8 -> Liliam-Lidia-Alberto | C6: =Bitácora!C8 -> 20 | D6: =Bitácora!M8 -> PQCA01001 | E6: =Bitácora!N8 -> 0 | F6: =Bitácora!O8 -> 0 | G6: =Bitácora!Q8 -> PQCA01001 | H6: =Bitácora!R8 -> 0
A7: =Bitácora!A9 -> 45994 | B7: =Bitácora!B9 -> Liliam-Lidia-Alberto | C7: =Bitácora!C9 -> 15 | D7: =Bitácora!M9 -> PAMP03017 | E7: =Bitácora!N9 -> 0 | F7: =Bitácora!O9 -> 0 | G7: =Bitácora!Q9 -> PAMP03017 | H7: =Bitácora!R9 -> 0
A8: =Bitácora!A10 -> 45994 | B8: =Bitácora!B10 -> Liliam-Lidia-Alberto | C8: =Bitácora!C10 -> 30 | D8: =Bitácora!M10 -> PAMP40017 | E8: =Bitácora!N10 -> 0 | F8: =Bitácora!O10 -> 0 | G8: =Bitácora!Q10 -> PAMP40017 | H8: =Bitácora!R10 -> 0
A9: =Bitácora!A11 -> 45995 | B9: =Bitácora!B11 -> Liliam-Lidia | C9: =Bitácora!C11 -> 31 | D9: =Bitácora!M11 -> PPBP07006 | E9: =Bitácora!N11 -> 31 Palmera pheonix bolsa 14*16 | F9: =Bitácora!O11 -> 31 Palmera pheonix bolsa 14*16 | G9: =Bitácora!Q11 -> PPBP07006 | H9: =Bitácora!R11 -> 0
A10: =Bitácora!A12 -> 45995 | B10: =Bitácora!B12 -> Liliam-Lidia | C10: =Bitácora!C12 -> 1 | D10: =Bitácora!M12 -> PAMP04128 | E10: =Bitácora!N12 -> 1 Aralia feliscifolia MP#4 dec | F10: =Bitácora!O12 -> 1 Aralia feliscifolia MP#4 dec | G10: =Bitácora!Q12 -> PAMP04128 | H10: =Bitácora!R12 -> 0
A11: =Bitácora!A13 -> 45995 | B11: =Bitácora!B13 -> Fermin-Julio | C11: =Bitácora!C13 -> 1 | D11: =Bitácora!M13 -> PCMP06040 | E11: =Bitácora!N13 -> 0 | F11: =Bitácora!O13 -> 0 | G11: =Bitácora!Q13 -> PCMP06040 | H11: =Bitácora!R13 -> 6000274
A12: =Bitácora!A14 -> 45995 | B12: =Bitácora!B14 -> Fermin-Julio | C12: =Bitácora!C14 -> 7 | D12: =Bitácora!M14 -> PSMP05013 | E12: =Bitácora!N14 -> 0 | F12: =Bitácora!O14 -> 0 | G12: =Bitácora!Q14 -> PSMP05013 | H12: =Bitácora!R14 -> 6000274
A13: =Bitácora!A15 -> 45995 | B13: =Bitácora!B15 -> Fermin-Julio | C13: =Bitácora!C15 -> 1 | D13: =Bitácora!M15 -> PFMP03120 | E13: =Bitácora!N15 -> 0 | F13: =Bitácora!O15 -> 0 | G13: =Bitácora!Q15 -> PFMP03120 | H13: =Bitácora!R15 -> 6000274
A14: =Bitácora!A16 -> 45995 | B14: =Bitácora!B16 -> Fermin-Julio | C14: =Bitácora!C16 -> 10 | D14: =Bitácora!M16 -> PCBP04038 | E14: =Bitácora!N16 -> 0 | F14: =Bitácora!O16 -> 0 | G14: =Bitácora!Q16 -> PCBP04038 | H14: =Bitácora!R16 -> 6000274
... A50: =Bitácora!A52 -> 0 | B50: =Bitácora!B52 -> 0 | C50: =Bitácora!C52 -> 0 | D50: =Bitácora!M52 -> 0 | E50: =Bitácora!N52 -> 0 | F50: =Bitácora!O52 -> 0 | G50: =Bitácora!Q52 -> 0 | H50: =Bitácora!R52 -> 0

Sheet Campo
A1: SEMBRADO A CAMPO
A2: Fecha | B2: Trabajador | C2: Cantidad | D2: Sembrar a campo/Sacar de campo | E2: A campo: Lugar de siembra | F2: Código
A3: =Bitácora!A5 -> 45992 | B3: =Bitácora!B5 -> liliam-Lidia | C3: =Bitácora!C5 -> 10 | D3: =Bitácora!K5 -> 0 | E3: =Bitácora!L5 -> 0 | F3: =Bitácora!Q5 -> PFMP03200
A4: =Bitácora!A6 -> 45992 | B4: =Bitácora!B6 -> Liliam-Lidia | C4: =Bitácora!C6 -> 15 | D4: =Bitácora!K6 -> 0 | E4: =Bitácora!L6 -> 0 | F4: =Bitácora!Q6 -> PAMP40017
A5: =Bitácora!A7 -> 45992 | B5: =Bitácora!B7 -> Julio-Alberto | C5: =Bitácora!C7 -> 500 | D5: =Bitácora!K7 -> 0 | E5: =Bitácora!L7 -> 0 | F5: =Bitácora!Q7 -> PGBP04001
A6: =Bitácora!A8 -> 45994 | B6: =Bitácora!B8 -> Liliam-Lidia-Alberto | C6: =Bitácora!C8 -> 20 | D6: =Bitácora!K8 -> 0 | E6: =Bitácora!L8 -> 0 | F6: =Bitácora!Q8 -> PQCA01001
A7: =Bitácora!A9 -> 45994 | B7: =Bitácora!B9 -> Liliam-Lidia-Alberto | C7: =Bitácora!C9 -> 15 | D7: =Bitácora!K9 -> 0 | E7: =Bitácora!L9 -> 0 | F7: =Bitácora!Q9 -> PAMP03017
A8: =Bitácora!A10 -> 45994 | B8: =Bitácora!B10 -> Liliam-Lidia-Alberto | C8: =Bitácora!C10 -> 30 | D8: =Bitácora!K10 -> 0 | E8: =Bitácora!L10 -> 0 | F8: =Bitácora!Q10 -> PAMP40017
A9: =Bitácora!A11 -> 45995 | B9: =Bitácora!B11 -> Liliam-Lidia | C9: =Bitácora!C11 -> 31 | D9: =Bitácora!K11 -> 0 | E9: =Bitácora!L11 -> 0 | F9: =Bitácora!Q11 -> PPBP07006
A10: =Bitácora!A12 -> 45995 | B10: =Bitácora!B12 -> Liliam-Lidia | C10: =Bitácora!C12 -> 1 | D10: =Bitácora!K12 -> 0 | E10: =Bitácora!L12 -> 0 | F10: =Bitácora!Q12 -> PAMP04128
A11: =Bitácora!A13 -> 45995 | B11: =Bitácora!B13 -> Fermin-Julio | C11: =Bitácora!C13 -> 1 | D11: =Bitácora!K13 -> 0 | E11: =Bitácora!L13 -> 0 | F11: =Bitácora!Q13 -> PCMP06040
A12: =Bitácora!A14 -> 45995 | B12: =Bitácora!B14 -> Fermin-Julio | C12: =Bitácora!C14 -> 7 | D12: =Bitácora!K14 -> 0 | E12: =Bitácora!L14 -> 0 | F12: =Bitácora!Q14 -> PSMP05013
A13: =Bitácora!A15 -> 45995 | B13: =Bitácora!B15 -> Fermin-Julio | C13: =Bitácora!C15 -> 1 | D13: =Bitácora!K15 -> 0 | E13: =Bitácora!L15 -> 0 | F13: =Bitácora!Q15 -> PFMP03120
A14: =Bitácora!A16 -> 45995 | B14: =Bitácora!B16 -> Fermin-Julio | C14: =Bitácora!C16 -> 10 | D14: =Bitácora!K16 -> 0 | E14: =Bitácora!L16 -> 0 | F14: =Bitácora!Q16 -> PCBP04038
... A49: =Bitácora!A51 -> 46001 | B49: =Bitácora!B51 -> Liliam-Lidia | C49: =Bitácora!C51 -> 29 | D49: =Bitácora!K51 -> 0 | E49: =Bitácora!L51 -> 0 | F49: =Bitácora!Q51 -> PCBP04104
A50: no hubo sembrado a campo

Sheet Hoja1
A1: CAPOSA S.A. DE C.V. Cantidades de sustrato por depositos
A2: Macetas | B2: Cantidad de sustrato
A3: 4 | B3: 400
A4: 5 | B4: 950
A5: 6 | B5: 1230
A6: MP#11 | B6: 10480
A7: Decorativas
A8: 1 | B8: 5000
A9: 2 | B9: 6500
A10: 3 | B10: 11300
A11: 4 | B11: 15600
A12: MPJ#1 | B12: 18560
A13: Bolsas
A14: 8*8 | B14: 2000
A15: 9*12 | B15: 6246
A16: 14*16 | B16: 15000
A17: 14*23 | B17: 15000
A18: Saco | B18: 110 libras
A19: PC#1 | B19: 6000
A20: Plato#3 | B20: 2500
